<mujoco model="aliengo">
  <compiler angle="radian" meshdir="assets" autolimits="true"/>

  <default>
    <default class="aliengo">
      <geom friction="0.4" margin="0.001" condim="1"/>
      <joint axis="0 1 0" damping="1" armature="0.1" frictionloss="0.2"/>
      <default class="abduction">
        <joint axis="1 0 0" range="-1.22173 1.22173"/>
      </default>
      <default class="hip">
        <default class="front_hip">
          <joint range="-1.5708 3.4907"/>
        </default>
        <default class="back_hip">
          <joint range="-0.5236 4.5379"/>
        </default>
      </default>
      <default class="knee">
        <joint range="-2.77507 -0.64577"/>
      </default>
      <default class="visual">
        <geom contype="0" conaffinity="0" group="2"/>
      </default>
      <default class="collision">
        <geom group="3"/>
        <default class="foot">
          <geom type="sphere" size="0.0265" pos="0 0 -0.25" priority="1" condim="6"
            friction="0.8 0.02 0.01"/>
        </default>
      </default>
    </default>
  </default>

  <asset>
    <mesh name="trunk" file="trunk.obj"/>
    <mesh name="hip" file="hip.obj"/>
    <mesh name="thigh" file="thigh.obj"/>
    <mesh name="thigh_mirror" file="thigh_mirror.obj"/>
    <mesh name="calf" file="calf.obj"/>
    <material name="metal" rgba=".9 .95 .95 1" />
    <material name="black" rgba="0 0 0 1" />
    <material name="white" rgba="1 1 1 1" />
    <material name="gray" rgba="0.671705 0.692426 0.774270 1" />
  </asset>

  <worldbody>
    <body name="trunk" pos="0 0 0.5" childclass="aliengo">
      <joint name="floating_base_joint" type="free"/>
      <inertial pos="0.008811 0.003839 0.000273" mass="11.644"
        fullinertia="0.051944892 0.24693924 0.270948307 0.001703617 0.000235941 0.000119783"/>
      <geom type="mesh" mesh="trunk" material="black" class="visual"/>
      <geom size="0.3235 0.075 0.056" type="box" material="black" class="collision"/>
      <site name="imu" pos="0 0 0"/>


      <!-- Front Left Leg -->
      <body name="FL_hip" pos="0.2407 0.051 0">
        <inertial pos="-0.022191 0.015144 -1.5e-05" mass="1.993"
          fullinertia="0.002446735 0.003925876 0.004148145 -0.00059805 1.945e-06 1.284e-06"/>
        <joint name="FL_hip_joint" class="abduction"/>
        <geom type="mesh" mesh="hip" material="black" class="visual"/>
        <geom type="cylinder" pos="0 0.083 0" euler="1.5708 0 0" size="0.046 0.0209" class="collision"/>
        <body name="FL_thigh" pos="0 0.0868 0">
          <inertial pos="-0.005607 -0.003877 -0.048199" mass="0.639"
            fullinertia="0.004173855 0.004343802 0.000340136 1.0284e-05 -0.000318874 0.000109233"/>
          <joint name="FL_thigh_joint" class="front_hip"/>
          <geom type="mesh" mesh="thigh" material="black" class="visual"/>
          <geom type="box" size="0.125 0.0187 0.0215" pos="0 0 -0.125" euler="0 1.5708 0" class="collision"/>
          <body name="FL_calf" pos="0 0 -0.25">
            <inertial pos="0.002781 6.3e-05 -0.142518" mass="0.207"
              fullinertia="0.002129279 0.002141463 3.7583e-05 3.9e-08 5.757e-06 -5.16e-07"/>
            <joint name="FL_calf_joint" class="knee"/>
            <geom type="mesh" mesh="calf" material="black" class="visual"/>
            <geom type="box" size="0.125 0.0104 0.008" pos="0 0 -0.125" euler="0 1.5708 0" class="collision"/>
            <geom name="FL" class="foot"/>
            <body name="FL_foot" pos="0 0 -0.25" >
                <inertial mass="0.00" pos="0 0 0" fullinertia="0.0001 0.0001 0.0001 0 0 0"/>
            </body>  
          </body>
        </body>
      </body>
      <!-- Front Right Leg -->
      <body name="FR_hip" pos="0.2407 -0.051 0">
        <inertial pos="-0.022191 -0.015144 -1.5e-05" mass="1.993"
          fullinertia="0.002446735 0.003925876 0.004148145 0.00059805 1.945e-06 -1.284e-06"/>
        <joint name="FR_hip_joint" class="abduction"/>
        <geom type="mesh" mesh="hip" material="black" class="visual" euler="3.1416 0 0"/>
        <geom type="cylinder" pos="0 -0.083 0" euler="1.5708 0 0" size="0.046 0.0209" class="collision"/>
        <body name="FR_thigh" pos="0 -0.0868 0">
          <inertial pos="-0.005607 0.003877 -0.048199" mass="0.639"
            fullinertia="0.004173855 0.004343802 0.000340136 -1.0284e-05 -0.000318874 -0.000109233"/>
          <joint name="FR_thigh_joint" class="front_hip"/>
          <geom type="mesh" mesh="thigh_mirror" material="black" class="visual" />
          <geom type="box" size="0.125 0.0187 0.0215" pos="0 0 -0.125" euler="0 1.5708 0" class="collision"/>
          <body name="FR_calf" pos="0 0 -0.25">
            <inertial pos="0.002781 6.3e-05 -0.142518" mass="0.207"
              fullinertia="0.002129279 0.002141463 3.7583e-05 3.9e-08 5.757e-06 -5.16e-07"/>
            <joint name="FR_calf_joint" class="knee" />
            <geom type="mesh" mesh="calf" material="black" class="visual"/>
            <geom type="box" size="0.125 0.0104 0.008" pos="0 0 -0.125" euler="0 1.5708 0" class="collision"/>
            <geom name="FR" class="foot"/>
            <body name="FR_foot" pos="0 0 -0.25" >
                <inertial mass="0.00" pos="0 0 0" fullinertia="0.0001 0.0001 0.0001 0 0 0"/>
            </body> 
          </body>
        </body>
      </body>

      <!-- Rear Left Leg -->
      <body name="RL_hip" pos="-0.2407 0.051 0">
        <inertial pos="0.022191 0.015144 -1.5e-05" mass="1.993"
          fullinertia="0.002446735 0.003925876 0.004148145 0.00059805 -1.945e-06 1.284e-06"/>
        <joint name="RL_hip_joint" class="abduction"/>
        <geom type="mesh" mesh="hip" material="black" class="visual" euler="0 3.1416 0"/>
        <geom type="cylinder" pos="0 0.083 0" euler="1.5708 0 0" size="0.046 0.0209" class="collision"/>
        <body name="RL_thigh" pos="0 0.0868 0">
          <inertial pos="-0.005607 -0.003877 -0.048199" mass="0.639"
            fullinertia="0.004173855 0.004343802 0.000340136 1.0284e-05 -0.000318874 0.000109233"/>
          <joint name="RL_thigh_joint" class="back_hip"/>
          <geom type="mesh" mesh="thigh" material="black" class="visual"/>
          <geom type="box" size="0.125 0.0187 0.0215" pos="0 0 -0.125" euler="0 1.5708 0" class="collision"/>
          <body name="RL_calf" pos="0 0 -0.25">
            <inertial pos="0.002781 6.3e-05 -0.142518" mass="0.207"
              fullinertia="0.002129279 0.002141463 3.7583e-05 3.9e-08 5.757e-06 -5.16e-07"/>
            <joint name="RL_calf_joint" class="knee"/>
            <geom type="mesh" mesh="calf" material="black" class="visual"/>
            <geom type="box" size="0.125 0.0104 0.008" pos="0 0 -0.125" euler="0 1.5708 0" class="collision"/>
            <geom name="RL" class="foot"/>
            <body name="RL_foot" pos="0 0 -0.25" >
                <inertial mass="0.00" pos="0 0 0" fullinertia="0.0001 0.0001 0.0001 0 0 0"/>
            </body>    
          </body>
        </body>
      </body>
    </body>

    <!-- Rear Right Leg -->
    <body name="RR_hip" pos="-0.2407 -0.051 0">
      <inertial pos="0.022191 -0.015144 -1.5e-05" mass="1.993"
        fullinertia="0.002446735 0.003925876 0.004148145 -0.00059805 -1.945e-06 -1.284e-06"/>
      <joint name="RR_hip_joint" class="abduction"/>
      <geom type="mesh" mesh="hip" material="black" class="visual" euler="3.1416 3.1416 0"/>
      <geom type="cylinder" pos="0 -0.083 0" euler="1.5708 0 0" size="0.046 0.0209" class="collision"/>
      <body name="RR_thigh" pos="0 -0.0868 0">
        <inertial pos="-0.005607 0.003877 -0.048199" mass="0.639"
          fullinertia="0.004173855 0.004343802 0.000340136 -1.0284e-05 -0.000318874 -0.000109233"/>
        <joint name="RR_thigh_joint" class="back_hip"/>
        <geom type="mesh" mesh="thigh_mirror" material="black" class="visual"/>
        <geom type="box" size="0.125 0.0187 0.0215" pos="0 0 -0.125" euler="0 1.5708 0" class="collision"/>
        <body name="RR_calf" pos="0 0 -0.25">
          <inertial pos="0.002781 6.3e-05 -0.142518" mass="0.207"
            fullinertia="0.002129279 0.002141463 3.7583e-05 3.9e-08 5.757e-06 -5.16e-07"/>
          <joint name="RR_calf_joint" class="knee"/>
          <geom type="mesh" mesh="calf" material="black" class="visual"/>
          <geom type="box" size="0.125 0.0104 0.008" pos="0 0 -0.125" euler="0 1.5708 0" class="collision"/>
          <geom name="RR" class="foot"/>
          <body name="RR_foot" pos="0 0 -0.25" >
              <inertial mass="0.00" pos="0 0 0" fullinertia="0.0001 0.0001 0.0001 0 0 0"/>
          </body>  
        </body>
      </body>
    </body>


  </worldbody>

  <actuator>
    <motor class="abduction"     ctrlrange="-35.278 35.278"               name="FL_hip" joint="FL_hip_joint"/>
    <motor class="hip"           ctrlrange="-35.278 35.278"               name="FL_thigh" joint="FL_thigh_joint"/>
    <motor class="knee"          ctrlrange="-44.4 44.4"               name="FL_calf" joint="FL_calf_joint"/>
    <motor class="abduction"     ctrlrange="-35.278 35.278"               name="FR_hip" joint="FR_hip_joint"/>
    <motor class="hip"           ctrlrange="-35.278 35.278"               name="FR_thigh" joint="FR_thigh_joint"/>
    <motor class="knee"          ctrlrange="-44.4 44.4"               name="FR_calf" joint="FR_calf_joint"/>
    <motor class="abduction"     ctrlrange="-35.278 35.278"               name="RL_hip" joint="RL_hip_joint"/>
    <motor class="hip"           ctrlrange="-35.278 35.278"               name="RL_thigh" joint="RL_thigh_joint"/>
    <motor class="knee"          ctrlrange="-44.4 44.4"               name="RL_calf" joint="RL_calf_joint"/>
    <motor class="abduction"     ctrlrange="-35.278 35.278"               name="RR_hip" joint="RR_hip_joint"/>
    <motor class="hip"           ctrlrange="-35.278 35.278"               name="RR_thigh" joint="RR_thigh_joint"/>
    <motor class="knee"          ctrlrange="-44.4 44.4"               name="RR_calf" joint="RR_calf_joint"/>
  </actuator>

  <sensor>
    <!-- Joint positions -->
    <jointpos name="FL_hip_pos" joint="FL_hip_joint"/>
    <jointpos name="FL_thigh_pos" joint="FL_thigh_joint"/>
    <jointpos name="FL_calf_pos" joint="FL_calf_joint"/>
    <jointpos name="FR_hip_pos" joint="FR_hip_joint"/>
    <jointpos name="FR_thigh_pos" joint="FR_thigh_joint"/>
    <jointpos name="FR_calf_pos" joint="FR_calf_joint"/>
    <jointpos name="RL_hip_pos" joint="RL_hip_joint"/>
    <jointpos name="RL_thigh_pos" joint="RL_thigh_joint"/>
    <jointpos name="RL_calf_pos" joint="RL_calf_joint"/>
    <jointpos name="RR_hip_pos" joint="RR_hip_joint"/>
    <jointpos name="RR_thigh_pos" joint="RR_thigh_joint"/>
    <jointpos name="RR_calf_pos" joint="RR_calf_joint"/>


    <!-- Joint velocities -->
    <jointvel name="FL_hip_vel" joint="FL_hip_joint"/>
    <jointvel name="FL_thigh_vel" joint="FL_thigh_joint"/>
    <jointvel name="FL_calf_vel" joint="FL_calf_joint"/>
    <jointvel name="FR_hip_vel" joint="FR_hip_joint"/>
    <jointvel name="FR_thigh_vel" joint="FR_thigh_joint"/>
    <jointvel name="FR_calf_vel" joint="FR_calf_joint"/>
    <jointvel name="RL_hip_vel" joint="RL_hip_joint"/>
    <jointvel name="RL_thigh_vel" joint="RL_thigh_joint"/>
    <jointvel name="RL_calf_vel" joint="RL_calf_joint"/>
    <jointvel name="RR_hip_vel" joint="RR_hip_joint"/>
    <jointvel name="RR_thigh_vel" joint="RR_thigh_joint"/>
    <jointvel name="RR_calf_vel" joint="RR_calf_joint"/>


    <!-- Joint torques -->
    <jointactuatorfrc name="FL_hip_torque" joint="FL_hip_joint" noise="0.01"/>
    <jointactuatorfrc name="FL_thigh_torque" joint="FL_thigh_joint" noise="0.01"/>
    <jointactuatorfrc name="FL_calf_torque" joint="FL_calf_joint" noise="0.01"/>
    <jointactuatorfrc name="FR_hip_torque" joint="FR_hip_joint" noise="0.01"/>
    <jointactuatorfrc name="FR_thigh_torque" joint="FR_thigh_joint" noise="0.01"/>
    <jointactuatorfrc name="FR_calf_torque" joint="FR_calf_joint" noise="0.01"/>
    <jointactuatorfrc name="RL_hip_torque" joint="RL_hip_joint" noise="0.01"/>
    <jointactuatorfrc name="RL_thigh_torque" joint="RL_thigh_joint" noise="0.01"/>
    <jointactuatorfrc name="RL_calf_torque" joint="RL_calf_joint" noise="0.01"/>
    <jointactuatorfrc name="RR_hip_torque" joint="RR_hip_joint" noise="0.01"/>
    <jointactuatorfrc name="RR_thigh_torque" joint="RR_thigh_joint" noise="0.01"/>
    <jointactuatorfrc name="RR_calf_torque" joint="RR_calf_joint" noise="0.01"/>


    <!-- IMU sensors -->
    <framequat name="imu_quat" objtype="site" objname="imu"/>
    <gyro name="imu_gyro" site="imu"/>
    <accelerometer name="imu_acc" site="imu"/>
    <framepos name="frame_pos" objtype="site" objname="imu" />
    <framelinvel name="frame_vel" objtype="site" objname="imu" />
    <!-- Base position and velocity -->
    <framepos name="base_pos" objtype="body" objname="trunk"/>
    <framelinvel name="base_vel" objtype="body" objname="trunk"/>
  </sensor>
</mujoco>
